Workbook

Sheet Cover
B1: Chemical Tanker Voyage Economics Model
A2: Independent analysis using publicly available data. Not affiliated with or endorsed by any organization named. | B2: Round-voyage TCE P&L, sensitivity/tornado, and break-even freight analysis — Sean Burgess, Sep-2026
B3: Independent analysis using publicly available data. Not affiliated with or endorsed by any organization named.
B4: SIMULATED / ESTIMATED INPUTS: freight rates, port costs, port days, vessel particulars and fuel-price conversion factors are analyst assumptions, not observed data. Canal tolls come from published tariff extracts; Brent and the freight index are public series.
B7: HEADLINE — ACTIVE SCENARIO
B8: Route | C8: =Voyage_PnL!B8 -> USG-ARA transatlantic
B9: Round-voyage days | C9: =Voyage_PnL!B20 -> 49.407407
B10: Gross freight | C10: =Voyage_PnL!B25 -> 2275200
B11: Total voyage costs | C11: =Voyage_PnL!B39 -> 1053581
B12: TCE ($/day) | C12: =Voyage_PnL!B43 -> 23574.178
B13: Vessel cost benchmark ($/day) | C13: =Benchmark -> 18000
B14: Voyage result after vessel cost | C14: =Voyage_PnL!B46 -> 275405.7
B15: Break-even fronthaul rate ($/t) | C15: =Voyage_PnL!B47 -> 42.76904
B16: Largest tornado driver | C16: =Sensitivity!A21 -> Freight rate (market)
B17: Model integrity check | C17: =Voyage_PnL!C60 -> OK
B20: HOW TO USE
B21: 1. Go to Inputs and change the five yellow scenario switches (route, bunker case, freight case, congestion, utilization).
B22: 2. Every assumption is a blue cell on Inputs / Routes / Canal_Tolls with its basis written next to it — overwrite any you disagree with.
B23: 3. Voyage_PnL shows the full cost build-up and TCE for the active scenario, plus all four routes side by side.
B24: 4. Sensitivity ranks the drivers (tornado) and shows leverage per +10% move; Breakeven shows break-even freight curves, a TCE heat-map and a speed curve.
B25: 5. Engine is the row-wise calculator behind the charts: one full voyage P&L per row. Do not edit it unless extending the model.
B27: COLOUR KEY
B28: Scenario switch
B29: Hardcoded input / assumption
B30: Key assumption
B31: Formula
B32: Link from another sheet
... B35: DEFINITIONS
B36: TCE | C36: (Gross freight - commissions - voyage costs) / voyage days. Converts a voyage charter into a $/day figure comparable with time-charter hire.
B37: Voyage costs | C37: Costs the shipowner bears on a voyage charter: bunkers, port disbursements, canal tolls, EU ETS allowances, misc.
B38: Fronthaul / backhaul | C38: Round voyage A->B (main cargo) then B->A (return cargo at lower utilization and rate). Backhaul utilization 0% = ballast return.
B39: Break-even rate | C39: Fronthaul $/t at which TCE equals the daily vessel-cost benchmark.
B40: ECA | C40: Emission Control Area — 0.10% sulphur limit, so MGO is burned inside (North American ECA, North Sea/Channel).
B42: SHEETS
B43: Inputs — switches and assumptions
B44: Routes — route & port-region tables
B45: Canal_Tolls — Panama & Suez per-transit build-up
B46: Voyage_PnL — detailed TCE build-up + route comparison
B47: Sensitivity — tornado + leverage
B48: Breakeven — break-even curves, TCE grid, speed curve
...

Sheet Inputs
A1: Inputs & scenario switches
A2: Independent analysis using publicly available data. Not affiliated with or endorsed by any organization named.
A3: Yellow cells = scenario switches. Blue = hardcoded assumption (edit freely). Black = formula. Every assumption carries its basis in column D.
A5: SCENARIO SWITCHES
A6: Switch | B6: Selection | C6: Resolves to | D6: Options
A7: 1. Route | B7: 1 | C7: =INDEX(Routes!$B$6:$B$9,Sw_Route) -> USG-ARA transatlantic | D7: 1 USG-ARA transatlantic | 2 USG-Far East via Panama | 3 ARA-India WC via Suez | 4 ARA-India WC via Cape
A8: 2. Bunker price case | B8: 1 | C8: =TEXT(Brent,"$0.00")&"/bbl Brent" -> $82.01/bbl Brent | D8: 1 Trailing-12m avg | 2 Latest month | 3 5-yr avg | 4 5-yr P10 | 5 5-yr P90 | 6 Custom (below)
A9: 3. Freight market case | B9: 1 | C9: =TEXT(FreightMult,"0.00")&"x base rates" -> 1.00x base rates | D9: 1 Base rates | 2 Weak (PPI YoY P10) | 3 Strong (PPI YoY P90) | 4 Custom multiplier (below)
A10: 4. Port congestion case | B10: 1 | C10: =TEXT(PortMult,"0.00")&"x port days" -> 1.00x port days | D10: 1 Normal (1.0x port days) | 2 Congested (1.5x) | 3 Severe (2.0x) | 4 Custom (below)
A11: 5. Cargo utilization case | B11: 1 | C11: =TEXT(UtilFH,"0%")&" / "&TEXT(UtilBH,"0%") -> 85% / 50% | D11: 1 Base (85% / 50%) | 2 Soft (70% / 25%) | 3 Firm (95% / 75%) | 4 Custom (below) [fronthaul / backhaul]
A13: CUSTOM OVERRIDES (used only when a switch selects 'Custom')
A14: Item | B14: Value | C14: Unit | D14: Note
A15: Custom Brent | B15: 80 | C15: $/bbl | D15: User entry
A16: Custom freight multiplier | B16: 1 | C16: x base rate | D16: User entry
A17: Custom port-time multiplier | B17: 1 | C17: x base port days | D17: User entry
A18: Custom fronthaul utilization | B18: 0.85 | C18: % capacity | D18: User entry
A19: Custom backhaul utilization | B19: 0.5 | C19: % capacity | D19: User entry (0% = ballast return)
A21: ACTIVE LEVERS (what the P&L uses — formulas, do not overwrite)
A22: Lever | B22: Active value | C22: Unit | D22: How resolved
A23: Brent crude | B23: =CHOOSE(Sw_Bunker,Brent_TTM,Brent_Latest,Brent_5Y,Brent_P10,Brent_P90,Cust_Brent) -> 82.01 | C23: $/bbl | D23: Switch 2 -> Data_Brent statistics (FRED MCOILBRENTEU)
A24: Freight rate multiplier | B24: =CHOOSE(Sw_Freight,1,Freight_Low,Freight_High,Cust_Freight) -> 1 | C24: x base rate | D24: Switch 3 -> Data_PPI percentile bands
A25: Port-time multiplier | B25: =CHOOSE(Sw_Port,1,1.5,2,Cust_Port) -> 1 | C25: x base port days | D25: Switch 4 (scenario bands, not a pulled series — USACE LPMS delay microdata is not public)
A26: Fronthaul utilization | B26: =CHOOSE(Sw_Util,0.85,0.7,0.95,Cust_UtilFH) -> 0.85 | C26: % capacity | D26: Switch 5
A27: Backhaul utilization | B27: =CHOOSE(Sw_Util,0.5,0.25,0.75,Cust_UtilBH) -> 0.5 | C27: % capacity | D27: Switch 5
A29: VESSEL — generic 38,000 dwt IMO II stainless-steel parcel chemical tanker
A30: Assumption | B30: Value | C30: Unit | D30: Basis / judgment (ESTIMATE unless a source is named)
A31: Deadweight | B31: 38000 | C31: t | D31: Typical deep-sea parcel tanker size class (32-45k dwt). Generic, not a specific ship.
A32: Usable cargo capacity | B32: 36000 | C32: t | D32: DWT less ~2,000 t bunkers, fresh water, stores, constant.
A33: Operating speed | B33: 13.5 | C33: knots | D33: Lever. Typical laden service speed 13-14.5 kn for this class.
A34: Reference speed for consumption | B34: 13.5 | C34: knots | D34: Speed at which the consumption figures below apply.
A35: Sea consumption, laden | B35: 27 | C35: t/day | D35: At reference speed. Non-eco 2010s-built design; eco ships ~20-24 t/day.
A36: Sea consumption, ballast | B36: 24 | C36: t/day | D36: At reference speed; applies to backhaul leg only when backhaul utilization = 0%.
A37: Port / canal consumption (MGO) | B37: 6 | C37: t/day | D37: Cargo pumps, heating, inerting, hotel load. Canal transit days burn at this rate (simplification).
A38: Consumption-speed exponent | B38: 3 | D38: Admiralty (cube) law; fuel per mile scales with speed squared.
A39: Sea margin | B39: 0.05 | C39: % of distance | D39: Weather and routeing allowance.
A40: Panama Canal net tonnage (PC/UMS) | B40: 20000 | C40: t | D40: Estimate for class; use the ship's certificate in practice.
A41: Suez Canal net tonnage (SCNT) | B41: 20000 | C41: t | D41: Estimate for class; use the ship's certificate in practice.
A42: Hull & machinery value | B42: 35000000 | C42: $ | D42: Used only for war-risk additional premium. Estimate.
A44: FUEL, CARBON & COMMERCIAL
A45: Assumption | B45: Value | C45: Unit | D45: Basis / judgment
...

Sheet Routes
A1: Routes and port regions
A2: Independent analysis using publicly available data. Not affiliated with or endorsed by any organization named.
A3: Round voyage: fronthaul A->B laden, backhaul B->A. Distances APPROXIMATE (verify with a distance table). Freight rates are CALIBRATED ASSUMPTIONS, not observed fixtures. Port costs come from the Port_Tariffs sheet.
A5: # | B5: Route | C5: Region A | D5: Region B | E5: Distance per leg (nm) | F5: ECA miles per leg (nm) | G5: Canal | H5: Canal days per transit | I5: EU ETS share of sea emissions | J5: Base freight fronthaul ($/t) | K5: Base freight backhaul ($/t) | L5: Port days per op, A | M5: Port days per op, B | N5: Fixed port cost per op, A ($) | O5: Fixed port cost per op, B ($) | P5: EU port A (1/0) | Q5: EU port B (1/0) | R5: Canal cost per laden transit ($) | S5: Canal cost per ballast transit ($) | T5: Cargo-based port rate A ($/t) | U5: Cargo-based port rate B ($/t) | V5: Cargo-component cap A ($) | W5: Cargo-component cap B ($) | X5: Berth-day share A | Y5: Berth-day share B
A6: 1 | B6: USG-ARA transatlantic | C6: USG | D6: ARA | E6: 5000 | F6: 650 | G6: None | H6: 0 | I6: 0.5 | J6: 52 | K6: 38 | L6: =INDEX($C$15:$C$18,MATCH(C6,$A$15:$A$18,0)) -> 5 | M6: =INDEX($C$15:$C$18,MATCH(D6,$A$15:$A$18,0)) -> 3.5 | N6: =INDEX($D$15:$D$18,MATCH(C6,$A$15:$A$18,0)) -> 45813.4 | O6: =INDEX($D$15:$D$18,MATCH(D6,$A$15:$A$18,0)) -> 44845.748 | P6: =INDEX($H$15:$H$18,MATCH(C6,$A$15:$A$18,0)) -> 0 | Q6: =INDEX($H$15:$H$18,MATCH(D6,$A$15:$A$18,0)) -> 1 | R6: =IF(G6="Panama",Canal_Tolls!$C$20,IF(G6="Suez",Canal_Tolls!$C$45,0)) -> 0 | S6: =IF(G6="Panama",Canal_Tolls!$D$20,IF(G6="Suez",Canal_Tolls!$D$45,0)) -> 0 | T6: =INDEX($E$15:$E$18,MATCH(C6,$A$15:$A$18,0)) -> 0 | U6: =INDEX($E$15:$E$18,MATCH(D6,$A$15:$A$18,0)) -> 0.655776 | V6: =INDEX($F$15:$F$18,MATCH(C6,$A$15:$A$18,0)) -> 0 | W6: =INDEX($F$15:$F$18,MATCH(D6,$A$15:$A$18,0)) -> 20542.511 | X6: =INDEX($G$15:$G$18,MATCH(C6,$A$15:$A$18,0)) -> 0.6 | Y6: =INDEX($G$15:$G$18,MATCH(D6,$A$15:$A$18,0)) -> 0
A7: 2 | B7: USG-Far East via Panama | C7: USG | D7: FEA | E7: 9650 | F7: 200 | G7: Panama | H7: 1.5 | I7: 0 | J7: 92 | K7: 52 | L7: =INDEX($C$15:$C$18,MATCH(C7,$A$15:$A$18,0)) -> 5 | M7: =INDEX($C$15:$C$18,MATCH(D7,$A$15:$A$18,0)) -> 3.5 | N7: =INDEX($D$15:$D$18,MATCH(C7,$A$15:$A$18,0)) -> 45813.4 | O7: =INDEX($D$15:$D$18,MATCH(D7,$A$15:$A$18,0)) -> 65000 | P7: =INDEX($H$15:$H$18,MATCH(C7,$A$15:$A$18,0)) -> 0 | Q7: =INDEX($H$15:$H$18,MATCH(D7,$A$15:$A$18,0)) -> 0 | R7: =IF(G7="Panama",Canal_Tolls!$C$20,IF(G7="Suez",Canal_Tolls!$C$45,0)) -> 213460 | S7: =IF(G7="Panama",Canal_Tolls!$D$20,IF(G7="Suez",Canal_Tolls!$D$45,0)) -> 186460 | T7: =INDEX($E$15:$E$18,MATCH(C7,$A$15:$A$18,0)) -> 0 | U7: =INDEX($E$15:$E$18,MATCH(D7,$A$15:$A$18,0)) -> 0 | V7: =INDEX($F$15:$F$18,MATCH(C7,$A$15:$A$18,0)) -> 0 | W7: =INDEX($F$15:$F$18,MATCH(D7,$A$15:$A$18,0)) -> 0 | X7: =INDEX($G$15:$G$18,MATCH(C7,$A$15:$A$18,0)) -> 0.6 | Y7: =INDEX($G$15:$G$18,MATCH(D7,$A$15:$A$18,0)) -> 0
A8: 3 | B8: ARA-India WC via Suez | C8: ARA | D8: IND | E8: 6350 | F8: 450 | G8: Suez | H8: 1 | I8: 0.5 | J8: 75 | K8: 55 | L8: =INDEX($C$15:$C$18,MATCH(C8,$A$15:$A$18,0)) -> 3.5 | M8: =INDEX($C$15:$C$18,MATCH(D8,$A$15:$A$18,0)) -> 4 | N8: =INDEX($D$15:$D$18,MATCH(C8,$A$15:$A$18,0)) -> 44845.748 | O8: =INDEX($D$15:$D$18,MATCH(D8,$A$15:$A$18,0)) -> 55000 | P8: =INDEX($H$15:$H$18,MATCH(C8,$A$15:$A$18,0)) -> 1 | Q8: =INDEX($H$15:$H$18,MATCH(D8,$A$15:$A$18,0)) -> 0 | R8: =IF(G8="Panama",Canal_Tolls!$C$20,IF(G8="Suez",Canal_Tolls!$C$45,0)) -> 376008 | S8: =IF(G8="Panama",Canal_Tolls!$D$20,IF(G8="Suez",Canal_Tolls!$D$45,0)) -> 330256.5 | T8: =INDEX($E$15:$E$18,MATCH(C8,$A$15:$A$18,0)) -> 0.655776 | U8: =INDEX($E$15:$E$18,MATCH(D8,$A$15:$A$18,0)) -> 0 | V8: =INDEX($F$15:$F$18,MATCH(C8,$A$15:$A$18,0)) -> 20542.511 | W8: =INDEX($F$15:$F$18,MATCH(D8,$A$15:$A$18,0)) -> 0 | X8: =INDEX($G$15:$G$18,MATCH(C8,$A$15:$A$18,0)) -> 0 | Y8: =INDEX($G$15:$G$18,MATCH(D8,$A$15:$A$18,0)) -> 0
A9: 4 | B9: ARA-India WC via Cape | C9: ARA | D9: IND | E9: 10850 | F9: 450 | G9: None | H9: 0 | I9: 0.5 | J9: 75 | K9: 55 | L9: =INDEX($C$15:$C$18,MATCH(C9,$A$15:$A$18,0)) -> 3.5 | M9: =INDEX($C$15:$C$18,MATCH(D9,$A$15:$A$18,0)) -> 4 | N9: =INDEX($D$15:$D$18,MATCH(C9,$A$15:$A$18,0)) -> 44845.748 | O9: =INDEX($D$15:$D$18,MATCH(D9,$A$15:$A$18,0)) -> 55000 | P9: =INDEX($H$15:$H$18,MATCH(C9,$A$15:$A$18,0)) -> 1 | Q9: =INDEX($H$15:$H$18,MATCH(D9,$A$15:$A$18,0)) -> 0 | R9: =IF(G9="Panama",Canal_Tolls!$C$20,IF(G9="Suez",Canal_Tolls!$C$45,0)) -> 0 | S9: =IF(G9="Panama",Canal_Tolls!$D$20,IF(G9="Suez",Canal_Tolls!$D$45,0)) -> 0 | T9: =INDEX($E$15:$E$18,MATCH(C9,$A$15:$A$18,0)) -> 0.655776 | U9: =INDEX($E$15:$E$18,MATCH(D9,$A$15:$A$18,0)) -> 0 | V9: =INDEX($F$15:$F$18,MATCH(C9,$A$15:$A$18,0)) -> 20542.511 | W9: =INDEX($F$15:$F$18,MATCH(D9,$A$15:$A$18,0)) -> 0 | X9: =INDEX($G$15:$G$18,MATCH(C9,$A$15:$A$18,0)) -> 0 | Y9: =INDEX($G$15:$G$18,MATCH(D9,$A$15:$A$18,0)) -> 0
B10: Distances: approximate great-circle/standard routeing figures (Houston-Rotterdam ~5,000 nm; Houston-Ulsan via Panama ~9,650 nm; Rotterdam-Mumbai ~6,350 nm via Suez / ~10,850 nm via Cape). Verify with a distance table (e.g., Netpas, BP Shipping Marine Distances).
A13: PORT REGIONS — port cost per operation = fixed + MIN(cargo tonnes x cargo rate, cap) + dockage (Port_Tariffs sheet)
A14: Code | B14: Region | C14: Port days per operation (incl. waiting) | D14: Fixed cost per op ($) | E14: Cargo rate ($/t) | F14: Cargo cap ($) | G14: Berth-day share | H14: EU port (1/0) | I14: Basis
A15: USG | B15: US Gulf (Houston) | C15: 5 | D15: =Port_Tariffs!$C$14 -> 45813.4 | E15: 0 | F15: 0 | G15: =Port_Tariffs!$C$11 -> 0.6 | H15: 0 | I15: PUBLISHED: Port Houston Tariff 14 harbor fee + LOA-based dockage (see Port_Tariffs). Pilotage, tugs, linesmen, agency and private-terminal charges are an estimate.
A16: ARA | B16: Amsterdam-Rotterdam-Antwerp | C16: 3.5 | D16: =Port_Tariffs!$C$29 -> 44845.748 | E16: =Port_Tariffs!$C$30 -> 0.655776 | F16: =Port_Tariffs!$C$31 -> 20542.511 | G16: 0 | H16: 1 | I16: PUBLISHED: Port of Rotterdam seaport dues — GT component + cargo component (capped) + sustainability component, 2025 schedule indexed 3.5% for 2026. Pilotage, tugs, boatmen and agency are an estimate.
A17: FEA | B17: Far East Asia (Korea/China) | C17: 3.5 | D17: 65000 | E17: 0 | F17: 0 | G17: 0 | H17: 0 | I17: ESTIMATE for Korea/China discharge — no published schedule transcribed.
A18: IND | B18: India West Coast | C18: 4 | D18: 55000 | E18: 0 | F18: 0 | G18: 0 | H18: 0 | I18: ESTIMATE for Kandla/Mumbai/JNPT discharge — no published schedule transcribed.

Sheet Port_Tariffs
A1: Port cost build-up from published tariffs
A2: Independent analysis using publicly available data. Not affiliated with or endorsed by any organization named.
A3: Blue cells are published tariff rates (sources named in column E) or estimated ancillary costs. Only the US Gulf and ARA legs have transcribed published schedules; Far East and India are lump-sum estimates.
A5: PORT HOUSTON — Tariff No. 14, effective 1 January 2025
A6: Source: porthouston.com/toolbox/rates/tariffs (Tariff 14 PDF), Subrules 095 (dockage) and 096 (harbor fee)
A7: Item | C7: Value | E7: Source / note
A8: Harbor fee, vessels 250 ft and over | C8: 813.4 | E8: Subrule 096, per entry into the Port Authority's jurisdictional limits. Published rate.
A9: Dockage rate, LOA 600-650 ft band | C9: 11.24 | E9: Subrule 095, $ per foot of LOA per 24 hours. Published rate. Applies at Port Authority wharves; private liquid terminals set their own dockage.
A10: Length overall (feet) | C10: =LOA_ft -> 600 | E10: From Inputs.
A11: Share of port days alongside (rest is waiting) | C11: 0.6 | E11: ESTIMATE. Waiting at anchorage incurs no dockage, so only berth time is charged.
A12: Berth days per operation, at the active port-time case | C12: =Routes!$C$15*C11*PortMult -> 3 | E12: Region port days x berth share x port-time multiplier.
A13: Dockage day-factor (tariff taper) | C13: =IF(C12<=2,C12,IF(C12<=3,2+0.9*(C12-2),IF(C12<=4,2.9+0.75*(C12-3),IF(C12<=5,3.65+0.6*(C12-4),4.25+0.5*(C12-5))))) -> 2.9 | E13: Subrule 095: days 1-2 at full rate, day 3 at 90%, day 4 at 75%, day 5 at 60%, day 6+ at 50%.
A14: FIXED cost per operation (harbor fee + ancillary) | C14: =C8+C15 -> 45813.4 | E14: Dockage is added per operation inside the model, because it moves with the congestion case.
A15: Ancillary: pilotage in/out, tugs, linesmen, agency, terminal | C15: 45000 | E15: ESTIMATE — replace with an agency proforma disbursement account.
A16: Illustrative dockage at the active case | C16: =LOA_ft*C9*C13 -> 19557.6 | E16: For reference; the model computes this per operation.
A20: PORT OF ROTTERDAM (ARA) — seaport dues, 2025 schedule indexed for 2026
A21: Source: Port of Rotterdam 'General terms and conditions including port tariffs', Annex 1 Tables 1-3 and the 133.3% chemical-tanker efficiency cap; portofrotterdam.com/en/port-dues-tariffs
A22: Item | C22: Value | E22: Source / note
A23: GT tariff, chemical/gas tanker (EUR per GT) | C23: 0.303 | E23: Table 1, rate type C. Published rate.
A24: Sustainability component (EUR per GT) | C24: 0.065 | E24: Table 3. No ESI or Green Award discount assumed — a Green Award certificate would cut this component by 70%.
A25: Cargo rate, other liquid bulk (EUR per tonne) | C25: 0.576 | E25: Table 2, commodity type 07. Published rate.
A26: Cargo-component cap, chemical tankers | C26: 1.333 | E26: Efficiency discount: cargo dues capped at GT x 133.3% x cargo rate. Published rule.
A27: 2026 indexation | C27: 1.035 | E27: Port of Rotterdam published a 3.5% indexation of port tariffs for 2026; applied to the 2025 schedule.
A28: Ancillary: pilotage, tugs, boatmen, agency, terminal | C28: 35000 | E28: ESTIMATE — replace with an agency proforma disbursement account.
A29: FIXED cost per operation ($) | C29: =GT*(C23+C24)*C27*FX+C28 -> 44845.748 | E29: Vessel and sustainability components, converted at the USD/EUR rate on Inputs.
A30: Cargo rate per tonne ($) | C30: =C25*C27*FX -> 0.655776 | E30: Applied to the tonnes loaded or discharged at this port.
A31: Cargo-component cap ($) | C31: =GT*C26*C25*C27*FX -> 20542.511
A32: Illustrative dues, 30,600 t discharge | C32: =C29-C28+MIN(30600*C30,C31) -> 29912.494 | E32: Sanity check against the worked example in the port's own annex.
A36: FAR EAST AND INDIA — no published schedule transcribed; lump-sum estimates on the Routes sheet.

Sheet Canal_Tolls
A1: Canal toll build-up (per transit)
A2: Independent analysis using publicly available data. Not affiliated with or endorsed by any organization named.
A3: Tariff values in blue are taken from the supplied extracts of official schedules (see data/README.md). Vessel tonnages and ancillaries are estimates.
A5: PANAMA CANAL — 'Super' vessel (beam > 91 ft), chemical tanker
A6: Item | B6: Tariff | C6: Laden ($) | D6: Ballast ($) | F6: Source / note
A7: Fixed tariff per transit (1010.FS01) | B7: 100000 | C7: =B7 -> 100000 | D7: =B7*$B$18 -> 85000 | F7: ACP tariff schedule; ballast pays 85% (1010.BA01)
A8: Capacity tariff per PC/UMS t, chemical (1010.QS01) | B8: 4 | C8: =B8*PCUMS -> 80000 | D8: =B8*PCUMS*$B$18 -> 68000 | F8: ACP tariff schedule x PC/UMS (Inputs)
A9: Mandatory tug, complete transit (Panamax locks) | B9: 7000 | C9: =B9 -> 7000 | D9: =B9 -> 7000 | F9: ACP schedule (regular-vessel rate used as proxy)
A10: Linehandling per linehandler (Panamax locks) | B10: 270 | C10: =B10*Linehandlers -> 2160 | D10: =B10*Linehandlers -> 2160 | F10: ACP schedule x linehandler count (Inputs)
A11: Transit reservation (Panamax) | B11: 10500 | C11: =B11 -> 10500 | D11: =B11 -> 10500 | F11: ACP schedule; optional in practice, included as base
A12: Security charge (PC/UMS >= 3,000) | B12: 1250 | C12: =B12 -> 1250 | D12: =B12 -> 1250 | F12: ACP schedule
A13: Fresh water surcharge, fixed (LOA > 91.44 m) | B13: 10000 | C13: =B13 -> 10000 | D13: =B13 -> 10000 | F13: ACP schedule; variable portion omitted
A14: Port pilotage, per call (x2: each end) | B14: 1275 | C14: =B14*2 -> 2550 | D14: =B14*2 -> 2550 | F14: ACP schedule
A18: Ballast factor (1010.BA01) | B18: 0.85
A20: Panama total per transit | C20: =SUM(C7:C14) -> 213460 | D20: =SUM(D7:D14) -> 186460
A24: SUEZ CANAL — petroleum-product-tanker bands (SDR per SCNT), Circular 7/2023
A25: Band | B25: Band size (SCNT) | C25: Laden SDR/t | D25: Ballast SDR/t | E25: SCNT in band | F25: Note
A26: First 5,000 | B26: 5000 | C26: 11.04 | D26: 9.4 | E26: =MAX(0,MIN(B26,SCNT-0)) -> 5000 | F26: Source: SCA Circular 7/2023 (eff. 15-Jan-2024) via shipping-agent mirror; see data/README.md
A27: Next 5,000 | B27: 5000 | C27: 7.82 | D27: 6.64 | E27: =MAX(0,MIN(B27,SCNT-SUM($B$26:B26))) -> 5000
A28: Next 10,000 | B28: 10000 | C28: 5.91 | D28: 5.04 | E28: =MAX(0,MIN(B28,SCNT-SUM($B$26:B27))) -> 10000
A29: Next 20,000 | B29: 20000 | C29: 3.93 | D29: 2.5 | E29: =MAX(0,MIN(B29,SCNT-SUM($B$26:B28))) -> 0
A30: Next 30,000 | B30: 30000 | C30: 3.84 | D30: 2.14 | E30: =MAX(0,MIN(B30,SCNT-SUM($B$26:B29))) -> 0
A31: Next 50,000 | B31: 50000 | C31: 3.46 | D31: 1.85 | E31: =MAX(0,MIN(B31,SCNT-SUM($B$26:B30))) -> 0
A32: The rest | B32: 1000000000 | C32: 3.34 | D32: 1.82 | E32: =MAX(0,MIN(B32,SCNT-SUM($B$26:B31))) -> 0
C34: Laden | D34: Ballast
A35: Base dues (SDR) | C35: =SUMPRODUCT(C26:C32,$E$26:$E$32) -> 153400 | D35: =SUMPRODUCT(D26:D32,$E$26:$E$32) -> 130600
A36: Tanker surcharge | C36: =SuezSurL -> 0.2 | D36: =SuezSurB -> 0.15 | F36: Chemical-tanker surcharge per safety4sea reporting of the same circular; bands are the product-tanker schedule (closest published proxy).
A37: Dues incl. surcharge (SDR) | C37: =C35*(1+C36) -> 184080 | D37: =D35*(1+D36) -> 150190
A38: USD per SDR | C38: =SDR_USD -> 1.35 | D38: =SDR_USD -> 1.35
A39: Transit dues ($) | C39: =C37*C38 -> 248508 | D39: =D37*D38 -> 202756.5
A40: Ancillaries: pilotage, tugs, mooring, agency ($, estimate) | C40: =SuezAnc -> 40000 | D40: =SuezAnc -> 40000
A41: War-risk additional premium ($, illustrative) | C41: =WarAP*HullValue -> 87500 | D41: =WarAP*HullValue -> 87500
A45: Suez total per transit | C45: =SUM(C39:C41) -> 376008 | D45: =SUM(D39:D41) -> 330256.5

Sheet Voyage_PnL
A1: Voyage P&L — Time Charter Equivalent build-up (active scenario)
A2: Independent analysis using publicly available data. Not affiliated with or endorsed by any organization named.
A3: Change scenario switches on the Inputs sheet. All values are formulas.
F6: ROUTE COMPARISON — active levers applied to every route
A7: SCENARIO | F7: Route | G7: Days | H7: Gross freight | I7: Bunkers | J7: Port | K7: Canal | L7: EU ETS | M7: Misc | N7: TCE $/day | O7: Result $ | P7: Break-even FH $/t
A8: Route | B8: =INDEX(Routes!$B$6:$B$9,Sw_Route) -> USG-ARA transatlantic | F8: =INDEX(Routes!$B$6:$B$9,1) -> USG-ARA transatlantic | G8: =Engine!AJ36 -> 49.407407 | H8: =Engine!AG36 -> 2275200 | I8: =Engine!Y36 -> 652340.34 | J8: =Engine!Z36 -> 252304.21 | K8: =Engine!AA36 -> 0 | L8: =Engine!AB36 -> 123936.41 | M8: =MiscVoy -> 25000 | N8: =Engine!AK36 -> 23574.178 | O8: =Engine!AL36 -> 275405.7 | P8: =Engine!AM36 -> 42.76904
A9: Brent / VLSFO / MGO | B9: =Brent -> 82.01 | C9: =TEXT(Brent*VLSFO_Mult,"$#,##0")&" / "&TEXT(Brent*MGO_Mult,"$#,##0")&" per t" -> $631 / $795 per t | D9: $/bbl; bunker $/t derived | F9: =INDEX(Routes!$B$6:$B$9,2) -> USG-Far East via Panama | G9: =Engine!AJ37 -> 82.546296 | H9: =Engine!AG37 -> 3751200 | I9: =Engine!Y37 -> 1167607.1 | J9: =Engine!Z37 -> 260742 | K9: =Engine!AA37 -> 426920 | L9: =Engine!AB37 -> 0 | M9: =MiscVoy -> 25000 | N9: =Engine!AK37 -> 21529.141 | O9: =Engine!AL37 -> 291317.54 | P9: =Engine!AM37 -> 82.235712
A10: Freight multiplier / port-time multiplier | B10: =FreightMult -> 1 | C10: =PortMult -> 1 | F10: =INDEX(Routes!$B$6:$B$9,3) -> ARA-India WC via Suez | G10: =Engine!AJ38 -> 58.157407 | H10: =Engine!AG38 -> 3285000 | I10: =Engine!Y38 -> 795786.09 | J10: =Engine!Z38 -> 231562.21 | K10: =Engine!AA38 -> 752016 | L10: =Engine!AB38 -> 154150.49 | M10: =MiscVoy -> 25000 | N10: =Engine!AK38 -> 21396.418 | O10: =Engine!AL38 -> 197526.88 | P10: =Engine!AM38 -> 68.379357
A11: Utilization fronthaul / backhaul | B11: =UtilFH -> 0.85 | C11: =UtilBH -> 0.5 | F11: =INDEX(Routes!$B$6:$B$9,4) -> ARA-India WC via Cape | G11: =Engine!AJ39 -> 85.324074 | H11: =Engine!AG39 -> 3285000 | I11: =Engine!Y39 -> 1283528.3 | J11: =Engine!Z39 -> 231562.21 | K11: =Engine!AA39 -> 0 | L11: =Engine!AB39 -> 255306.83 | M11: =MiscVoy -> 25000 | N11: =Engine!AK39 -> 16495.669 | O11: =Engine!AL39 -> -128355.63 | P11: =Engine!AM39 -> 79.302183
A13: VOYAGE TIME | B13: Days
A14: Distance per leg (nm) | B14: =INDEX(Routes!$E$6:$E$9,Sw_Route) -> 5000 | D14: Routes sheet
A15: Sea days, fronthaul | B15: =B14*(1+SeaMargin)/(Speed*24) -> 16.203704 | D15: distance x (1 + sea margin) / (speed x 24)
A16: Sea days, backhaul | B16: =B15 -> 16.203704 | D16: same distance
A17: Port days, region A | B17: =INDEX(Routes!$L$6:$L$9,Sw_Route)*(1+IF(UtilBH>0,1,0))*PortMult -> 10 | D17: days per operation x operations x port-time multiplier
A18: Port days, region B | B18: =INDEX(Routes!$M$6:$M$9,Sw_Route)*(1+IF(UtilBH>0,1,0))*PortMult -> 7 | D18: an operation = a load or a discharge; a backhaul cargo adds one at each end
A19: Canal days | B19: =INDEX(Routes!$H$6:$H$9,Sw_Route)*2 -> 0 | D19: two transits
A20: Total voyage days | B20: =SUM(B15:B19) -> 49.407407
A22: REVENUE | B22: $
A23: Fronthaul cargo (t) x rate ($/t) | B23: =Capacity*UtilFH -> 30600 | C23: =INDEX(Routes!$J$6:$J$9,Sw_Route)*FreightMult -> 52 | D23: B = tonnes, C = $/t
A24: Backhaul cargo (t) x rate ($/t) | B24: =Capacity*UtilBH -> 18000 | C24: =INDEX(Routes!$K$6:$K$9,Sw_Route)*FreightMult -> 38
A25: Gross freight | B25: =B23*C23+B24*C24 -> 2275200
A26: Less: commissions | B26: =-B25*Commission -> -56880 | D26: address + brokerage
A27: Net freight | B27: =B25+B26 -> 2218320
A29: VOYAGE COSTS | B29: $ | C29: t
A30: Speed factor (consumption vs reference) | B30: =(Speed/RefSpeed)^SpeedExp -> 1 | D30: cube law
A31: Sea fuel, both legs (t) | B31: =B15*B30*ConsLaden+B16*B30*IF(UtilBH>0,ConsLaden,ConsBallast) -> 875
A32: ECA share of sea miles | B32: =INDEX(Routes!$F$6:$F$9,Sw_Route)/B14 -> 0.13 | D32: burns MGO
A33: VLSFO cost (sea, outside ECA) | B33: =C33*Brent*VLSFO_Mult -> 480711.87 | C33: =B31*(1-B32) -> 761.25 | D33: C = tonnes
A34: MGO cost (ECA + port + canal) | B34: =C34*Brent*MGO_Mult -> 171628.48 | C34: =B31*B32+(B17+B18+B19)*ConsPort -> 215.75 | D34: C = tonnes
A35: Port disbursements | B35: =(INDEX(Routes!$N$6:$N$9,Sw_Route)+LOA_ft*Port_Tariffs!$C$9*IF((INDEX(Routes!$L$6:$L$9,Sw_Route)*INDEX(Routes!$X$6:$X$9,Sw_Route)*PortMult)<=2,(INDEX(Routes!$L$6:$L$9,Sw_Route)*INDEX(Routes!$X$6:$X$9,Sw_Route)*PortMult),IF((INDEX(Routes!$L$6:$L$9,Sw_Route)*INDEX(Routes!$X$6:$X$9,Sw_Route)*PortMult)<=3,2+0.9*((INDEX(Routes!$L$6:$L$9,Sw_Route)*INDEX(Routes!$X$6:$X$9,Sw_Route)*PortMult)-2),IF((INDEX(Routes!$L$6:$L$9,Sw_Route)*INDEX(Routes!$X$6:$X$9,Sw_Route)*PortMult)<=4,2.9+0.75*((INDEX(Routes!$L$6:$L$9,Sw_Route)*INDEX(Routes!$X$6:$X$9,Sw_Route)*PortMult)-3),IF((INDEX(Routes!$L$6:$L$9,Sw_Route)*INDEX(Routes!$X$6:$X$9,Sw_Route)*PortMult)<=5,3.65+0.6*((INDEX(Routes!$L$6:$L$9,Sw_Route)*INDEX(Routes!$X$6:$X$9,Sw_Route)*PortMult)-4),4.25+0.5*((INDEX(Routes!$L$6:$L$9,Sw_Route)*INDEX(Routes!$X$6:$X$9,Sw_Route)*PortMult)-5)))))+MIN(B23*INDEX(Routes!$T$6:$T$9,Sw_Route),INDEX(Routes!$V$6:$V$9,Sw_Route))+INDEX(Routes!$O$6:$O$9,Sw_Route)+LOA_ft*Port_Tariffs!$C$9*IF((INDEX(Routes!$M$6:$M$9,Sw_Route)*INDEX(Routes!$Y$6:$Y$9,Sw_Route)*PortMult)<=2,(INDEX(Routes!$M$6:$M$9,Sw_Route)*INDEX(Routes!$Y$6:$Y$9,Sw_Route)*PortMult),IF((INDEX(Routes!$M$6:$M$9,Sw_Route)*INDEX(Routes!$Y$6:$Y$9,Sw_Route)*PortMult)<=3,2+0.9*((INDEX(Routes!$M$6:$M$9,Sw_Route)*INDEX(Routes!$Y$6:$Y$9,Sw_Route)*PortMult)-2),IF((INDEX(Routes!$M$6:$M$9,Sw_Route)*INDEX(Routes!$Y$6:$Y$9,Sw_Route)*PortMult)<=4,2.9+0.75*((INDEX(Routes!$M$6:$M$9,Sw_Route)*INDEX(Routes!$Y$6:$Y$9,Sw_Route)*PortMult)-3),IF((INDEX(Routes!$M$6:$M$9,Sw_Route)*INDEX(Routes!$Y$6:$Y$9,Sw_Route)*PortMult)<=5,3.65+0.6*((INDEX(Routes!$M$6:$M$9,Sw_Route)*INDEX(Routes!$Y$6:$Y$9,Sw_Route)*PortMult)-4),4.25+0.5*((INDEX(Routes!$M$6:$M$9,Sw_Route)*INDEX(Routes!$Y$6:$Y$9,Sw_Route)*PortMult)-5)))))+MIN(B23*INDEX(Routes!$U$6:$U$9,Sw_Route),INDEX(Routes!$W$6:$W$9,Sw_Route))+IF(UtilBH>0,INDEX(Routes!$N$6:$N$9,Sw_Route)+LOA_ft*Port_Tariffs!$C$9*IF((INDEX(Routes!$L$6:$L$9,Sw_Route)*INDEX(Routes!$X$6:$X$9,Sw_Route)*PortMult)<=2,(INDEX(Routes!$L$6:$L$9,Sw_Route)*INDEX(Routes!$X$6:$X$9,Sw_Route)*PortMult),IF((INDEX(Routes!$L$6:$L$9,Sw_Route)*INDEX(Routes!$X$6:$X$9,Sw_Route)*PortMult)<=3,2+0.9*((INDEX(Routes!$L$6:$L$9,Sw_Route)*INDEX(Routes!$X$6:$X$9,Sw_Route)*PortMult)-2),IF((INDEX(Routes!$L$6:$L$9,Sw_Route)*INDEX(Routes!$X$6:$X$9,Sw_Route)*PortMult)<=4,2.9+0.75*((INDEX(Routes!$L$6:$L$9,Sw_Route)*INDEX(Routes!$X$6:$X$9,Sw_Route)*PortMult)-3),IF((INDEX(Routes!$L$6:$L$9,Sw_Route)*INDEX(Routes!$X$6:$X$9,Sw_Route)*PortMult)<=5,3.65+0.6*((INDEX(Routes!$L$6:$L$9,Sw_Route)*INDEX(Routes!$X$6:$X$9,Sw_Route)*PortMult)-4),4.25+0.5*((INDEX(Routes!$L$6:$L$9,Sw_Route)*INDEX(Routes!$X$6:$X$9,Sw_Route)*PortMult)-5)))))+MIN(B24*INDEX(Routes!$T$6:$T$9,Sw_Route),INDEX(Routes!$V$6:$V$9,Sw_Route))+INDEX(Routes!$O$6:$O$9,Sw_Route)+LOA_ft*Port_Tariffs!$C$9*IF((INDEX(Routes!$M$6:$M$9,Sw_Route)*INDEX(Routes!$Y$6:$Y$9,Sw_Route)*PortMult)<=2,(INDEX(Routes!$M$6:$M$9,Sw_Route)*INDEX(Routes!$Y$6:$Y$9,Sw_Route)*PortMult),IF((INDEX(Routes!$M$6:$M$9,Sw_Route)*INDEX(Routes!$Y$6:$Y$9,Sw_Route)*PortMult)<=3,2+0.9*((INDEX(Routes!$M$6:$M$9,Sw_Route)*INDEX(Routes!$Y$6:$Y$9,Sw_Route)*PortMult)-2),IF((INDEX(Routes!$M$6:$M$9,Sw_Route)*INDEX(Routes!$Y$6:$Y$9,Sw_Route)*PortMult)<=4,2.9+0.75*((INDEX(Routes!$M$6:$M$9,Sw_Route)*INDEX(Routes!$Y$6:$Y$9,Sw_Route)*PortMult)-3),IF((INDEX(Routes!$M$6:$M$9,Sw_Route)*INDEX(Routes!$Y$6:$Y$9,Sw_Route)*PortMult)<=5,3.65+0.6*((INDEX(Routes!$M$6:$M$9,Sw_Route)*INDEX(Routes!$Y$6:$Y$9,Sw_Route)*PortMult)-4),4.25+0.5*((INDEX(Routes!$M$6:$M$9,Sw_Route)*INDEX(Routes!$Y$6:$Y$9,Sw_Route)*PortMult)-5)))))+MIN(B24*INDEX(Routes!$U$6:$U$9,Sw_Route),INDEX(Routes!$W$6:$W$9,Sw_Route)),0))*PortCostMult -> 252304.21 | D35: Published Port Houston / Rotterdam tariffs + estimated ancillaries (Port_Tariffs sheet)
A36: Canal tolls & transit costs | B36: =INDEX(Routes!$R$6:$R$9,Sw_Route)+IF(UtilBH>0,INDEX(Routes!$R$6:$R$9,Sw_Route),INDEX(Routes!$S$6:$S$9,Sw_Route)) -> 0 | D36: Canal_Tolls sheet
A37: EU ETS allowances | B37: =((C33*CO2_VLSFO+B31*B32*CO2_MGO)*INDEX(Routes!$I$6:$I$9,Sw_Route)+(B17*INDEX(Routes!$P$6:$P$9,Sw_Route)+B18*INDEX(Routes!$Q$6:$Q$9,Sw_Route))*ConsPort*CO2_MGO)*PhaseIn*EUA*FX -> 123936.41 | D37: 50% of extra-EU voyage emissions + 100% at EU berth
A38: Misc. voyage costs | B38: =MiscVoy -> 25000
A39: Total voyage costs | B39: =SUM(B33:B38) -> 1053581
A41: RESULT
A42: Voyage net revenue (net freight - voyage costs) | B42: =B27-B39 -> 1164739
A43: TIME CHARTER EQUIVALENT ($/day) | B43: =B42/B20 -> 23574.178 | D43: the headline commercial metric
A44: Daily vessel cost benchmark ($/day) | B44: =Benchmark -> 18000 | D44: OPEX + capital, or T/C-in hire
A45: TCE margin over benchmark ($/day) | B45: =B43-B44 -> 5574.1784
A46: Voyage result after vessel cost ($) | B46: =B45*B20 -> 275405.7
...

Sheet Sensitivity
A1: Sensitivity — what drives TCE?
A2: Independent analysis using publicly available data. Not affiliated with or endorsed by any organization named.
A3: Tornado: each lever moved across a plausible range with everything else at the active scenario. Freight and Brent ranges are data-derived (Data_PPI, Data_Brent); the rest are judgment bands.
A5: Base TCE (active scenario) | B5: =Engine!AK7 -> 23574.178
A7: A. Tornado input table (unsorted)
A8: Lever | B8: Low value | C8: High value | D8: Unit | E8: TCE at low | F8: TCE at high | G8: Swing $/day | H8: Sort key
A9: Freight rate (market) | B9: =Engine!E9 -> 0.91 | C9: =Engine!E10 -> 1.25 | D9: x base rate | E9: =Engine!AK9 -> 19533.311 | F9: =Engine!AK10 -> 34798.811 | G9: =ABS(F9-E9) -> 15265.5 | H9: =G9+ROW()/1000000 -> 15265.5
A10: Bunker price (Brent) | B10: =Engine!D11 -> 67.98 | C10: =Engine!D12 -> 104.84 | D10: $/bbl | E10: =Engine!AK11 -> 25832.954 | F10: =Engine!AK12 -> 19898.637 | G10: =ABS(F10-E10) -> 5934.3163 | H10: =G10+ROW()/1000000 -> 5934.3163
A11: Port time (congestion) | B11: =Engine!F13 -> 0.75 | C11: =Engine!F14 -> 1.75 | D11: x base port days | E11: =Engine!AK13 -> 26505.193 | F11: =Engine!AK14 -> 17305.373 | G11: =ABS(F11-E11) -> 9199.8201 | H11: =G11+ROW()/1000000 -> 9199.8202
A12: Fronthaul utilization | B12: =Engine!G15 -> 0.7 | C12: =Engine!G16 -> 0.95 | D12: % capacity | E12: =Engine!AK15 -> 18104.577 | F12: =Engine!AK16 -> 27258.732 | G12: =ABS(F12-E12) -> 9154.1546 | H12: =G12+ROW()/1000000 -> 9154.1546
A13: Backhaul utilization | B13: =Engine!H17 -> 0.25 | C13: =Engine!H18 -> 0.75 | D13: % capacity | E13: =Engine!AK17 -> 16944.646 | F13: =Engine!AK18 -> 30203.711 | G13: =ABS(F13-E13) -> 13259.065 | H13: =G13+ROW()/1000000 -> 13259.065
A14: Service speed | B14: =Engine!I19 -> 12 | C14: =Engine!I20 -> 14.5 | D14: knots | E14: =Engine!AK19 -> 24473.272 | F14: =Engine!AK20 -> 22463.307 | G14: =ABS(F14-E14) -> 2009.9644 | H14: =G14+ROW()/1000000 -> 2009.9644
A15: Port disbursements | B15: =Engine!J21 -> 0.75 | C15: =Engine!J22 -> 1.25 | D15: x base | E15: =Engine!AK21 -> 24850.83 | F15: =Engine!AK22 -> 22297.527 | G15: =ABS(F15-E15) -> 2553.3035 | H15: =G15+ROW()/1000000 -> 2553.3035
A16: EU carbon price (EUA) | B16: =Engine!K23 -> 50 | C16: =Engine!K24 -> 110 | D16: EUR/t | E16: =Engine!AK23 -> 24410.331 | F16: =Engine!AK24 -> 22403.565 | G16: =ABS(F16-E16) -> 2006.7664 | H16: =G16+ROW()/1000000 -> 2006.7665
A19: B. Tornado — ranked by swing (chart source)
A20: Lever | B20: Low -> TCE change | C20: High -> TCE change | D20: Swing $/day | E20: Low value | F20: High value | G20: Rank
A21: =INDEX($A$9:$A$16,MATCH(LARGE($H$9:$H$16,1),$H$9:$H$16,0)) -> Freight rate (market) | B21: =INDEX($E$9:$E$16,MATCH(LARGE($H$9:$H$16,1),$H$9:$H$16,0))-$B$5 -> -4040.8678 | C21: =INDEX($F$9:$F$16,MATCH(LARGE($H$9:$H$16,1),$H$9:$H$16,0))-$B$5 -> 11224.633 | D21: =INDEX($G$9:$G$16,MATCH(LARGE($H$9:$H$16,1),$H$9:$H$16,0)) -> 15265.5 | E21: =INDEX($B$9:$B$16,MATCH(LARGE($H$9:$H$16,1),$H$9:$H$16,0)) -> 0.91 | F21: =INDEX($C$9:$C$16,MATCH(LARGE($H$9:$H$16,1),$H$9:$H$16,0)) -> 1.25 | G21: 1
A22: =INDEX($A$9:$A$16,MATCH(LARGE($H$9:$H$16,2),$H$9:$H$16,0)) -> Backhaul utilization | B22: =INDEX($E$9:$E$16,MATCH(LARGE($H$9:$H$16,2),$H$9:$H$16,0))-$B$5 -> -6629.5326 | C22: =INDEX($F$9:$F$16,MATCH(LARGE($H$9:$H$16,2),$H$9:$H$16,0))-$B$5 -> 6629.5326 | D22: =INDEX($G$9:$G$16,MATCH(LARGE($H$9:$H$16,2),$H$9:$H$16,0)) -> 13259.065 | E22: =INDEX($B$9:$B$16,MATCH(LARGE($H$9:$H$16,2),$H$9:$H$16,0)) -> 0.25 | F22: =INDEX($C$9:$C$16,MATCH(LARGE($H$9:$H$16,2),$H$9:$H$16,0)) -> 0.75 | G22: 2
A23: =INDEX($A$9:$A$16,MATCH(LARGE($H$9:$H$16,3),$H$9:$H$16,0)) -> Port time (congestion) | B23: =INDEX($E$9:$E$16,MATCH(LARGE($H$9:$H$16,3),$H$9:$H$16,0))-$B$5 -> 2931.0148 | C23: =INDEX($F$9:$F$16,MATCH(LARGE($H$9:$H$16,3),$H$9:$H$16,0))-$B$5 -> -6268.8053 | D23: =INDEX($G$9:$G$16,MATCH(LARGE($H$9:$H$16,3),$H$9:$H$16,0)) -> 9199.8201 | E23: =INDEX($B$9:$B$16,MATCH(LARGE($H$9:$H$16,3),$H$9:$H$16,0)) -> 0.75 | F23: =INDEX($C$9:$C$16,MATCH(LARGE($H$9:$H$16,3),$H$9:$H$16,0)) -> 1.75 | G23: 3
A24: =INDEX($A$9:$A$16,MATCH(LARGE($H$9:$H$16,4),$H$9:$H$16,0)) -> Fronthaul utilization | B24: =INDEX($E$9:$E$16,MATCH(LARGE($H$9:$H$16,4),$H$9:$H$16,0))-$B$5 -> -5469.6011 | C24: =INDEX($F$9:$F$16,MATCH(LARGE($H$9:$H$16,4),$H$9:$H$16,0))-$B$5 -> 3684.5535 | D24: =INDEX($G$9:$G$16,MATCH(LARGE($H$9:$H$16,4),$H$9:$H$16,0)) -> 9154.1546 | E24: =INDEX($B$9:$B$16,MATCH(LARGE($H$9:$H$16,4),$H$9:$H$16,0)) -> 0.7 | F24: =INDEX($C$9:$C$16,MATCH(LARGE($H$9:$H$16,4),$H$9:$H$16,0)) -> 0.95 | G24: 4
A25: =INDEX($A$9:$A$16,MATCH(LARGE($H$9:$H$16,5),$H$9:$H$16,0)) -> Bunker price (Brent) | B25: =INDEX($E$9:$E$16,MATCH(LARGE($H$9:$H$16,5),$H$9:$H$16,0))-$B$5 -> 2258.7753 | C25: =INDEX($F$9:$F$16,MATCH(LARGE($H$9:$H$16,5),$H$9:$H$16,0))-$B$5 -> -3675.541 | D25: =INDEX($G$9:$G$16,MATCH(LARGE($H$9:$H$16,5),$H$9:$H$16,0)) -> 5934.3163 | E25: =INDEX($B$9:$B$16,MATCH(LARGE($H$9:$H$16,5),$H$9:$H$16,0)) -> 67.98 | F25: =INDEX($C$9:$C$16,MATCH(LARGE($H$9:$H$16,5),$H$9:$H$16,0)) -> 104.84 | G25: 5
A26: =INDEX($A$9:$A$16,MATCH(LARGE($H$9:$H$16,6),$H$9:$H$16,0)) -> Port disbursements | B26: =INDEX($E$9:$E$16,MATCH(LARGE($H$9:$H$16,6),$H$9:$H$16,0))-$B$5 -> 1276.6517 | C26: =INDEX($F$9:$F$16,MATCH(LARGE($H$9:$H$16,6),$H$9:$H$16,0))-$B$5 -> -1276.6517 | D26: =INDEX($G$9:$G$16,MATCH(LARGE($H$9:$H$16,6),$H$9:$H$16,0)) -> 2553.3035 | E26: =INDEX($B$9:$B$16,MATCH(LARGE($H$9:$H$16,6),$H$9:$H$16,0)) -> 0.75 | F26: =INDEX($C$9:$C$16,MATCH(LARGE($H$9:$H$16,6),$H$9:$H$16,0)) -> 1.25 | G26: 6
A27: =INDEX($A$9:$A$16,MATCH(LARGE($H$9:$H$16,7),$H$9:$H$16,0)) -> Service speed | B27: =INDEX($E$9:$E$16,MATCH(LARGE($H$9:$H$16,7),$H$9:$H$16,0))-$B$5 -> 899.09328 | C27: =INDEX($F$9:$F$16,MATCH(LARGE($H$9:$H$16,7),$H$9:$H$16,0))-$B$5 -> -1110.8711 | D27: =INDEX($G$9:$G$16,MATCH(LARGE($H$9:$H$16,7),$H$9:$H$16,0)) -> 2009.9644 | E27: =INDEX($B$9:$B$16,MATCH(LARGE($H$9:$H$16,7),$H$9:$H$16,0)) -> 12 | F27: =INDEX($C$9:$C$16,MATCH(LARGE($H$9:$H$16,7),$H$9:$H$16,0)) -> 14.5 | G27: 7
A28: =INDEX($A$9:$A$16,MATCH(LARGE($H$9:$H$16,8),$H$9:$H$16,0)) -> EU carbon price (EUA) | B28: =INDEX($E$9:$E$16,MATCH(LARGE($H$9:$H$16,8),$H$9:$H$16,0))-$B$5 -> 836.15268 | C28: =INDEX($F$9:$F$16,MATCH(LARGE($H$9:$H$16,8),$H$9:$H$16,0))-$B$5 -> -1170.6138 | D28: =INDEX($G$9:$G$16,MATCH(LARGE($H$9:$H$16,8),$H$9:$H$16,0)) -> 2006.7664 | E28: =INDEX($B$9:$B$16,MATCH(LARGE($H$9:$H$16,8),$H$9:$H$16,0)) -> 50 | F28: =INDEX($C$9:$C$16,MATCH(LARGE($H$9:$H$16,8),$H$9:$H$16,0)) -> 110 | G28: 8
A32: C. Leverage — TCE change for a +10% move in each lever (apples-to-apples)
A33: Lever | B33: Base value | C33: +10% value | D33: TCE change $/day | E33: Per 1% move $/day
A34: Freight rate | B34: =FreightMult -> 1 | C34: =Engine!E27 -> 1.1 | D34: =Engine!AK27-$B$5 -> 4489.8531 | E34: =D34/10 -> 448.98531
A35: Bunker price | B35: =Brent -> 82.01 | C35: =Engine!D28 -> 90.211 | D35: =Engine!AK28-$B$5 -> -1320.329 | E35: =D35/10 -> -132.0329
A36: Port time | B36: =PortMult -> 1 | C36: =Engine!F29 -> 1.1 | D36: =Engine!AK29-$B$5 -> -1024.0365 | E36: =D36/10 -> -102.40365
A37: Fronthaul utilization | B37: =UtilFH -> 0.85 | C37: =Engine!G30 -> 0.935 | D37: =Engine!AK30-$B$5 -> 3130.426 | E37: =D37/10 -> 313.0426
A38: Backhaul utilization | B38: =UtilBH -> 0.5 | C38: =Engine!H31 -> 0.55 | D38: =Engine!AK31-$B$5 -> 1325.9065 | E38: =D38/10 -> 132.59065
A39: Service speed | B39: =Speed -> 13.5 | C39: =Engine!I32 -> 14.85 | D39: =Engine!AK32-$B$5 -> -1596.882 | E39: =D39/10 -> -159.6882
A40: Port disbursements | B40: =PortCostMult -> 1 | C40: =Engine!J33 -> 1.1 | D40: =Engine!AK33-$B$5 -> -510.66069 | E40: =D40/10 -> -51.066069
A43: Reading the two views together: the tornado answers 'what moved results most over realistic ranges'; the +10% table answers 'where does one unit of effort buy the most TCE'. Utilization and speed are partly controllable; freight and bunker prices are mostly not.

Sheet Breakeven
A1: Break-even fronthaul freight rate ($/t) — the rate at which TCE equals the daily vessel cost benchmark
A2: Independent analysis using publicly available data. Not affiliated with or endorsed by any organization named.
A3: Curves hold the active route and levers constant except the ones named. Linear in Brent because bunker cost is linear in price.
A5: A. By port-time multiplier (active route)
A6: Brent $/bbl | B6: 1.0x port time | C6: 1.5x port time | D6: 2.0x port time
A7: 50 | B7: =Engine!AM42 -> 34.234756 | C7: =Engine!AM51 -> 40.852882 | D7: =Engine!AM60 -> 47.357987
A8: 60 | B8: =Engine!AM43 -> 36.900887 | C8: =Engine!AM52 -> 43.684825 | D8: =Engine!AM61 -> 50.355741
A9: 70 | B9: =Engine!AM44 -> 39.567017 | C9: =Engine!AM53 -> 46.516767 | D9: =Engine!AM62 -> 53.353496
A10: 80 | B10: =Engine!AM45 -> 42.233147 | C10: =Engine!AM54 -> 49.348709 | D10: =Engine!AM63 -> 56.35125
A11: 90 | B11: =Engine!AM46 -> 44.899278 | C11: =Engine!AM55 -> 52.180652 | D11: =Engine!AM64 -> 59.349004
A12: 100 | B12: =Engine!AM47 -> 47.565408 | C12: =Engine!AM56 -> 55.012594 | D12: =Engine!AM65 -> 62.346759
A13: 110 | B13: =Engine!AM48 -> 50.231539 | C13: =Engine!AM57 -> 57.844537 | D13: =Engine!AM66 -> 65.344513
A14: 120 | B14: =Engine!AM49 -> 52.897669 | C14: =Engine!AM58 -> 60.676479 | D14: =Engine!AM67 -> 68.342267
A15: 130 | B15: =Engine!AM50 -> 55.563799 | C15: =Engine!AM59 -> 63.508421 | D15: =Engine!AM68 -> 71.340022
A19: B. By fronthaul utilization (active route)
A20: Brent $/bbl | B20: 70% utilization | C20: 85% utilization | D20: 95% utilization
A21: 50 | B21: =Engine!AM69 -> 41.426649 | C21: =Engine!AM78 -> 34.234756 | D21: =Engine!AM87 -> 30.645366
A22: 60 | B22: =Engine!AM70 -> 44.664093 | C22: =Engine!AM79 -> 36.900887 | D22: =Engine!AM88 -> 33.030851
A23: 70 | B23: =Engine!AM71 -> 47.901537 | C23: =Engine!AM80 -> 39.567017 | D23: =Engine!AM89 -> 35.416336
A24: 80 | B24: =Engine!AM72 -> 51.138981 | C24: =Engine!AM81 -> 42.233147 | D24: =Engine!AM90 -> 37.801821
A25: 90 | B25: =Engine!AM73 -> 54.376425 | C25: =Engine!AM82 -> 44.899278 | D25: =Engine!AM91 -> 40.187306
A26: 100 | B26: =Engine!AM74 -> 57.613869 | C26: =Engine!AM83 -> 47.565408 | D26: =Engine!AM92 -> 42.572791
A27: 110 | B27: =Engine!AM75 -> 60.851313 | C27: =Engine!AM84 -> 50.231539 | D27: =Engine!AM93 -> 44.958276
A28: 120 | B28: =Engine!AM76 -> 64.088757 | C28: =Engine!AM85 -> 52.897669 | D28: =Engine!AM94 -> 47.343761
A29: 130 | B29: =Engine!AM77 -> 67.326201 | C29: =Engine!AM86 -> 55.563799 | D29: =Engine!AM95 -> 49.729246
A33: C. By route (active levers)
A34: Brent $/bbl | B34: =Routes!B6 -> USG-ARA transatlantic | C34: =Routes!B7 -> USG-Far East via Panama | D34: =Routes!B8 -> ARA-India WC via Suez | E34: =Routes!B9 -> ARA-India WC via Cape | F34: Base rate R1 | G34: Base rate R2 | H34: Base rate R3 | I34: Base rate R4
A35: 50 | B35: =Engine!AM96 -> 34.234756 | C35: =Engine!AM105 -> 66.960418 | D35: =Engine!AM114 -> 57.968436 | E35: =Engine!AM123 -> 62.510344 | F35: =Routes!$J$6*FreightMult -> 52 | G35: =Routes!$J$7*FreightMult -> 92 | H35: =Routes!$J$8*FreightMult -> 75 | I35: =Routes!$J$9*FreightMult -> 75
A36: 60 | B36: =Engine!AM97 -> 36.900887 | C36: =Engine!AM106 -> 71.732456 | D36: =Engine!AM115 -> 61.220832 | E36: =Engine!AM124 -> 67.756155 | F36: =Routes!$J$6*FreightMult -> 52 | G36: =Routes!$J$7*FreightMult -> 92 | H36: =Routes!$J$8*FreightMult -> 75 | I36: =Routes!$J$9*FreightMult -> 75
A37: 70 | B37: =Engine!AM98 -> 39.567017 | C37: =Engine!AM107 -> 76.504494 | D37: =Engine!AM116 -> 64.473229 | E37: =Engine!AM125 -> 73.001965 | F37: =Routes!$J$6*FreightMult -> 52 | G37: =Routes!$J$7*FreightMult -> 92 | H37: =Routes!$J$8*FreightMult -> 75 | I37: =Routes!$J$9*FreightMult -> 75
A38: 80 | B38: =Engine!AM99 -> 42.233147 | C38: =Engine!AM108 -> 81.276532 | D38: =Engine!AM117 -> 67.725625 | E38: =Engine!AM126 -> 78.247775 | F38: =Routes!$J$6*FreightMult -> 52 | G38: =Routes!$J$7*FreightMult -> 92 | H38: =Routes!$J$8*FreightMult -> 75 | I38: =Routes!$J$9*FreightMult -> 75
A39: 90 | B39: =Engine!AM100 -> 44.899278 | C39: =Engine!AM109 -> 86.04857 | D39: =Engine!AM118 -> 70.978022 | E39: =Engine!AM127 -> 83.493586 | F39: =Routes!$J$6*FreightMult -> 52 | G39: =Routes!$J$7*FreightMult -> 92 | H39: =Routes!$J$8*FreightMult -> 75 | I39: =Routes!$J$9*FreightMult -> 75
A40: 100 | B40: =Engine!AM101 -> 47.565408 | C40: =Engine!AM110 -> 90.820608 | D40: =Engine!AM119 -> 74.230418 | E40: =Engine!AM128 -> 88.739396 | F40: =Routes!$J$6*FreightMult -> 52 | G40: =Routes!$J$7*FreightMult -> 92 | H40: =Routes!$J$8*FreightMult -> 75 | I40: =Routes!$J$9*FreightMult -> 75
A41: 110 | B41: =Engine!AM102 -> 50.231539 | C41: =Engine!AM111 -> 95.592646 | D41: =Engine!AM120 -> 77.482815 | E41: =Engine!AM129 -> 93.985206 | F41: =Routes!$J$6*FreightMult -> 52 | G41: =Routes!$J$7*FreightMult -> 92 | H41: =Routes!$J$8*FreightMult -> 75 | I41: =Routes!$J$9*FreightMult -> 75
A42: 120 | B42: =Engine!AM103 -> 52.897669 | C42: =Engine!AM112 -> 100.36468 | D42: =Engine!AM121 -> 80.735211 | E42: =Engine!AM130 -> 99.231016 | F42: =Routes!$J$6*FreightMult -> 52 | G42: =Routes!$J$7*FreightMult -> 92 | H42: =Routes!$J$8*FreightMult -> 75 | I42: =Routes!$J$9*FreightMult -> 75
A43: 130 | B43: =Engine!AM104 -> 55.563799 | C43: =Engine!AM113 -> 105.13672 | D43: =Engine!AM122 -> 83.987608 | E43: =Engine!AM131 -> 104.47683 | F43: =Routes!$J$6*FreightMult -> 52 | G43: =Routes!$J$7*FreightMult -> 92 | H43: =Routes!$J$8*FreightMult -> 75 | I43: =Routes!$J$9*FreightMult -> 75
A47: D. TCE grid ($/day): freight multiplier (rows) x Brent (columns), active route
A48: Freight mult \ Brent | B48: $60 | C48: $70 | D48: $80 | E48: $90 | F48: $100 | G48: $110 | H48: $120
A49: 0.8 | B49: =Engine!AK134 -> 18137.996 | C49: =Engine!AK135 -> 16528.035 | D49: =Engine!AK136 -> 14918.074 | E49: =Engine!AK137 -> 13308.113 | F49: =Engine!AK138 -> 11698.152 | G49: =Engine!AK139 -> 10088.191 | H49: =Engine!AK140 -> 8478.2304
A50: 0.9 | B50: =Engine!AK141 -> 22627.85 | C50: =Engine!AK142 -> 21017.889 | D50: =Engine!AK143 -> 19407.928 | E50: =Engine!AK144 -> 17797.966 | F50: =Engine!AK145 -> 16188.005 | G50: =Engine!AK146 -> 14578.044 | H50: =Engine!AK147 -> 12968.083
...

Sheet Engine
A1: Calculation engine — one full round-voyage P&L per row
A2: Independent analysis using publicly available data. Not affiliated with or endorsed by any organization named.
A3: Each row recomputes the whole voyage with its own lever values (cols C-K). Sensitivity and Breakeven sheets read from here. Row 7 = active scenario and must equal Voyage_PnL (check on that sheet).
A6: Case | B6: Group | C6: Route # | D6: Brent $/bbl | E6: Freight mult | F6: Port-time mult | G6: Util FH | H6: Util BH | I6: Speed kn | J6: Port-cost mult | K6: EUA EUR/t | L6: Distance/leg nm | M6: ECA share | N6: Sea days (both legs) | O6: Speed factor | P6: Backhaul laden? | Q6: Sea fuel t | R6: VLSFO t | S6: MGO sea t | T6: Port ops per region | U6: Port days A | V6: Port days B | W6: Canal days | X6: MGO port t | Y6: Bunker cost $ | Z6: Port cost $ | AA6: Canal cost $ | AB6: EU ETS cost $ | AC6: Qty FH t | AD6: Qty BH t | AE6: Rate FH $/t | AF6: Rate BH $/t | AG6: Gross freight $ | AH6: Commission $ | AI6: Voyage costs $ | AJ6: Voyage days | AK6: TCE $/day | AL6: Voyage result $ | AM6: Break-even FH rate $/t
A7: Active scenario | B7: base | C7: =Sw_Route -> 1 | D7: =Brent -> 82.01 | E7: =FreightMult -> 1 | F7: =PortMult -> 1 | G7: =UtilFH -> 0.85 | H7: =UtilBH -> 0.5 | I7: =Speed -> 13.5 | J7: =PortCostMult -> 1 | K7: =EUA -> 75 | L7: =INDEX(Routes!$E$6:$E$9,$C7) -> 5000 | M7: =INDEX(Routes!$F$6:$F$9,$C7)/L7 -> 0.13 | N7: =2*L7*(1+SeaMargin)/(I7*24) -> 32.407407 | O7: =(I7/RefSpeed)^SpeedExp -> 1 | P7: =IF(H7>0,1,0) -> 1 | Q7: =N7/2*O7*(ConsLaden+IF(P7=1,ConsLaden,ConsBallast)) -> 875 | R7: =Q7*(1-M7) -> 761.25 | S7: =Q7*M7 -> 113.75 | T7: =1+P7 -> 2 | U7: =INDEX(Routes!$L$6:$L$9,$C7)*T7*F7 -> 10 | V7: =INDEX(Routes!$M$6:$M$9,$C7)*T7*F7 -> 7 | W7: =INDEX(Routes!$H$6:$H$9,$C7)*2 -> 0 | X7: =(U7+V7+W7)*ConsPort -> 102 | Y7: =R7*D7*VLSFO_Mult+(S7+X7)*D7*MGO_Mult -> 652340.34 | Z7: =(INDEX(Routes!$N$6:$N$9,$C7)+AN7+MIN(AC7*INDEX(Routes!$T$6:$T$9,$C7),INDEX(Routes!$V$6:$V$9,$C7))+INDEX(Routes!$O$6:$O$9,$C7)+AO7+MIN(AC7*INDEX(Routes!$U$6:$U$9,$C7),INDEX(Routes!$W$6:$W$9,$C7))+IF(P7=1,INDEX(Routes!$N$6:$N$9,$C7)+AN7+MIN(AD7*INDEX(Routes!$T$6:$T$9,$C7),INDEX(Routes!$V$6:$V$9,$C7))+INDEX(Routes!$O$6:$O$9,$C7)+AO7+MIN(AD7*INDEX(Routes!$U$6:$U$9,$C7),INDEX(Routes!$W$6:$W$9,$C7)),0))*J7 -> 252304.21 | AA7: =INDEX(Routes!$R$6:$R$9,$C7)+IF(P7=1,INDEX(Routes!$R$6:$R$9,$C7),INDEX(Routes!$S$6:$S$9,$C7)) -> 0 | AB7: =((R7*CO2_VLSFO+S7*CO2_MGO)*INDEX(Routes!$I$6:$I$9,$C7)+(U7*INDEX(Routes!$P$6:$P$9,$C7)+V7*INDEX(Routes!$Q$6:$Q$9,$C7))*ConsPort*CO2_MGO)*PhaseIn*K7*FX -> 123936.41 | AC7: =Capacity*G7 -> 30600 | AD7: =Capacity*H7 -> 18000 | AE7: =INDEX(Routes!$J$6:$J$9,$C7)*E7 -> 52 | AF7: =INDEX(Routes!$K$6:$K$9,$C7)*E7 -> 38 | AG7: =AC7*AE7+AD7*AF7 -> 2275200 | AH7: =AG7*Commission -> 56880 | AI7: =Y7+Z7+AA7+AB7+MiscVoy -> 1053581 | AJ7: =N7+U7+V7+W7 -> 49.407407 | AK7: =(AG7-AH7-AI7)/AJ7 -> 23574.178 | AL7: =AG7-AH7-AI7-Benchmark*AJ7 -> 275405.7 | AM7: =IF(AC7>0,((Benchmark*AJ7+AI7)/(1-Commission)-AD7*AF7)/AC7,0) -> 42.76904 | AN7: =LOA_ft*Port_Tariffs!$C$9*IF((INDEX(Routes!$L$6:$L$9,$C7)*INDEX(Routes!$X$6:$X$9,$C7)*F7)<=2,(INDEX(Routes!$L$6:$L$9,$C7)*INDEX(Routes!$X$6:$X$9,$C7)*F7),IF((INDEX(Routes!$L$6:$L$9,$C7)*INDEX(Routes!$X$6:$X$9,$C7)*F7)<=3,2+0.9*((INDEX(Routes!$L$6:$L$9,$C7)*INDEX(Routes!$X$6:$X$9,$C7)*F7)-2),IF((INDEX(Routes!$L$6:$L$9,$C7)*INDEX(Routes!$X$6:$X$9,$C7)*F7)<=4,2.9+0.75*((INDEX(Routes!$L$6:$L$9,$C7)*INDEX(Routes!$X$6:$X$9,$C7)*F7)-3),IF((INDEX(Routes!$L$6:$L$9,$C7)*INDEX(Routes!$X$6:$X$9,$C7)*F7)<=5,3.65+0.6*((INDEX(Routes!$L$6:$L$9,$C7)*INDEX(Routes!$X$6:$X$9,$C7)*F7)-4),4.25+0.5*((INDEX(Routes!$L$6:$L$9,$C7)*INDEX(Routes!$X$6:$X$9,$C7)*F7)-5))))) -> 19557.6 | AO7: =LOA_ft*Port_Tariffs!$C$9*IF((INDEX(Routes!$M$6:$M$9,$C7)*INDEX(Routes!$Y$6:$Y$9,$C7)*F7)<=2,(INDEX(Routes!$M$6:$M$9,$C7)*INDEX(Routes!$Y$6:$Y$9,$C7)*F7),IF((INDEX(Routes!$M$6:$M$9,$C7)*INDEX(Routes!$Y$6:$Y$9,$C7)*F7)<=3,2+0.9*((INDEX(Routes!$M$6:$M$9,$C7)*INDEX(Routes!$Y$6:$Y$9,$C7)*F7)-2),IF((INDEX(Routes!$M$6:$M$9,$C7)*INDEX(Routes!$Y$6:$Y$9,$C7)*F7)<=4,2.9+0.75*((INDEX(Routes!$M$6:$M$9,$C7)*INDEX(Routes!$Y$6:$Y$9,$C7)*F7)-3),IF((INDEX(Routes!$M$6:$M$9,$C7)*INDEX(Routes!$Y$6:$Y$9,$C7)*F7)<=5,3.65+0.6*((INDEX(Routes!$M$6:$M$9,$C7)*INDEX(Routes!$Y$6:$Y$9,$C7)*F7)-4),4.25+0.5*((INDEX(Routes!$M$6:$M$9,$C7)*INDEX(Routes!$Y$6:$Y$9,$C7)*F7)-5))))) -> 0
A8: TORNADO CASES (one lever flexed, all others at active values)
A9: Freight rate (market) — low | B9: tornado | C9: =Sw_Route -> 1 | D9: =Brent -> 82.01 | E9: =Freight_Low -> 0.91 | F9: =PortMult -> 1 | G9: =UtilFH -> 0.85 | H9: =UtilBH -> 0.5 | I9: =Speed -> 13.5 | J9: =PortCostMult -> 1 | K9: =EUA -> 75 | L9: =INDEX(Routes!$E$6:$E$9,$C9) -> 5000 | M9: =INDEX(Routes!$F$6:$F$9,$C9)/L9 -> 0.13 | N9: =2*L9*(1+SeaMargin)/(I9*24) -> 32.407407 | O9: =(I9/RefSpeed)^SpeedExp -> 1 | P9: =IF(H9>0,1,0) -> 1 | Q9: =N9/2*O9*(ConsLaden+IF(P9=1,ConsLaden,ConsBallast)) -> 875 | R9: =Q9*(1-M9) -> 761.25 | S9: =Q9*M9 -> 113.75 | T9: =1+P9 -> 2 | U9: =INDEX(Routes!$L$6:$L$9,$C9)*T9*F9 -> 10 | V9: =INDEX(Routes!$M$6:$M$9,$C9)*T9*F9 -> 7 | W9: =INDEX(Routes!$H$6:$H$9,$C9)*2 -> 0 | X9: =(U9+V9+W9)*ConsPort -> 102 | Y9: =R9*D9*VLSFO_Mult+(S9+X9)*D9*MGO_Mult -> 652340.34 | Z9: =(INDEX(Routes!$N$6:$N$9,$C9)+AN9+MIN(AC9*INDEX(Routes!$T$6:$T$9,$C9),INDEX(Routes!$V$6:$V$9,$C9))+INDEX(Routes!$O$6:$O$9,$C9)+AO9+MIN(AC9*INDEX(Routes!$U$6:$U$9,$C9),INDEX(Routes!$W$6:$W$9,$C9))+IF(P9=1,INDEX(Routes!$N$6:$N$9,$C9)+AN9+MIN(AD9*INDEX(Routes!$T$6:$T$9,$C9),INDEX(Routes!$V$6:$V$9,$C9))+INDEX(Routes!$O$6:$O$9,$C9)+AO9+MIN(AD9*INDEX(Routes!$U$6:$U$9,$C9),INDEX(Routes!$W$6:$W$9,$C9)),0))*J9 -> 252304.21 | AA9: =INDEX(Routes!$R$6:$R$9,$C9)+IF(P9=1,INDEX(Routes!$R$6:$R$9,$C9),INDEX(Routes!$S$6:$S$9,$C9)) -> 0 | AB9: =((R9*CO2_VLSFO+S9*CO2_MGO)*INDEX(Routes!$I$6:$I$9,$C9)+(U9*INDEX(Routes!$P$6:$P$9,$C9)+V9*INDEX(Routes!$Q$6:$Q$9,$C9))*ConsPort*CO2_MGO)*PhaseIn*K9*FX -> 123936.41 | AC9: =Capacity*G9 -> 30600 | AD9: =Capacity*H9 -> 18000 | AE9: =INDEX(Routes!$J$6:$J$9,$C9)*E9 -> 47.32 | AF9: =INDEX(Routes!$K$6:$K$9,$C9)*E9 -> 34.58 | AG9: =AC9*AE9+AD9*AF9 -> 2070432 | AH9: =AG9*Commission -> 51760.8 | AI9: =Y9+Z9+AA9+AB9+MiscVoy -> 1053581 | AJ9: =N9+U9+V9+W9 -> 49.407407 | AK9: =(AG9-AH9-AI9)/AJ9 -> 19533.311 | AL9: =AG9-AH9-AI9-Benchmark*AJ9 -> 75756.904 | AM9: =IF(AC9>0,((Benchmark*AJ9+AI9)/(1-Commission)-AD9*AF9)/AC9,0) -> 44.780804 | AN9: =LOA_ft*Port_Tariffs!$C$9*IF((INDEX(Routes!$L$6:$L$9,$C9)*INDEX(Routes!$X$6:$X$9,$C9)*F9)<=2,(INDEX(Routes!$L$6:$L$9,$C9)*INDEX(Routes!$X$6:$X$9,$C9)*F9),IF((INDEX(Routes!$L$6:$L$9,$C9)*INDEX(Routes!$X$6:$X$9,$C9)*F9)<=3,2+0.9*((INDEX(Routes!$L$6:$L$9,$C9)*INDEX(Routes!$X$6:$X$9,$C9)*F9)-2),IF((INDEX(Routes!$L$6:$L$9,$C9)*INDEX(Routes!$X$6:$X$9,$C9)*F9)<=4,2.9+0.75*((INDEX(Routes!$L$6:$L$9,$C9)*INDEX(Routes!$X$6:$X$9,$C9)*F9)-3),IF((INDEX(Routes!$L$6:$L$9,$C9)*INDEX(Routes!$X$6:$X$9,$C9)*F9)<=5,3.65+0.6*((INDEX(Routes!$L$6:$L$9,$C9)*INDEX(Routes!$X$6:$X$9,$C9)*F9)-4),4.25+0.5*((INDEX(Routes!$L$6:$L$9,$C9)*INDEX(Routes!$X$6:$X$9,$C9)*F9)-5))))) -> 19557.6 | AO9: =LOA_ft*Port_Tariffs!$C$9*IF((INDEX(Routes!$M$6:$M$9,$C9)*INDEX(Routes!$Y$6:$Y$9,$C9)*F9)<=2,(INDEX(Routes!$M$6:$M$9,$C9)*INDEX(Routes!$Y$6:$Y$9,$C9)*F9),IF((INDEX(Routes!$M$6:$M$9,$C9)*INDEX(Routes!$Y$6:$Y$9,$C9)*F9)<=3,2+0.9*((INDEX(Routes!$M$6:$M$9,$C9)*INDEX(Routes!$Y$6:$Y$9,$C9)*F9)-2),IF((INDEX(Routes!$M$6:$M$9,$C9)*INDEX(Routes!$Y$6:$Y$9,$C9)*F9)<=4,2.9+0.75*((INDEX(Routes!$M$6:$M$9,$C9)*INDEX(Routes!$Y$6:$Y$9,$C9)*F9)-3),IF((INDEX(Routes!$M$6:$M$9,$C9)*INDEX(Routes!$Y$6:$Y$9,$C9)*F9)<=5,3.65+0.6*((INDEX(Routes!$M$6:$M$9,$C9)*INDEX(Routes!$Y$6:$Y$9,$C9)*F9)-4),4.25+0.5*((INDEX(Routes!$M$6:$M$9,$C9)*INDEX(Routes!$Y$6:$Y$9,$C9)*F9)-5))))) -> 0
A10: Freight rate (market) — high | B10: tornado | C10: =Sw_Route -> 1 | D10: =Brent -> 82.01 | E10: =Freight_High -> 1.25 | F10: =PortMult -> 1 | G10: =UtilFH -> 0.85 | H10: =UtilBH -> 0.5 | I10: =Speed -> 13.5 | J10: =PortCostMult -> 1 | K10: =EUA -> 75 | L10: =INDEX(Routes!$E$6:$E$9,$C10) -> 5000 | M10: =INDEX(Routes!$F$6:$F$9,$C10)/L10 -> 0.13 | N10: =2*L10*(1+SeaMargin)/(I10*24) -> 32.407407 | O10: =(I10/RefSpeed)^SpeedExp -> 1 | P10: =IF(H10>0,1,0) -> 1 | Q10: =N10/2*O10*(ConsLaden+IF(P10=1,ConsLaden,ConsBallast)) -> 875 | R10: =Q10*(1-M10) -> 761.25 | S10: =Q10*M10 -> 113.75 | T10: =1+P10 -> 2 | U10: =INDEX(Routes!$L$6:$L$9,$C10)*T10*F10 -> 10 | V10: =INDEX(Routes!$M$6:$M$9,$C10)*T10*F10 -> 7 | W10: =INDEX(Routes!$H$6:$H$9,$C10)*2 -> 0 | X10: =(U10+V10+W10)*ConsPort -> 102 | Y10: =R10*D10*VLSFO_Mult+(S10+X10)*D10*MGO_Mult -> 652340.34 | Z10: =(INDEX(Routes!$N$6:$N$9,$C10)+AN10+MIN(AC10*INDEX(Routes!$T$6:$T$9,$C10),INDEX(Routes!$V$6:$V$9,$C10))+INDEX(Routes!$O$6:$O$9,$C10)+AO10+MIN(AC10*INDEX(Routes!$U$6:$U$9,$C10),INDEX(Routes!$W$6:$W$9,$C10))+IF(P10=1,INDEX(Routes!$N$6:$N$9,$C10)+AN10+MIN(AD10*INDEX(Routes!$T$6:$T$9,$C10),INDEX(Routes!$V$6:$V$9,$C10))+INDEX(Routes!$O$6:$O$9,$C10)+AO10+MIN(AD10*INDEX(Routes!$U$6:$U$9,$C10),INDEX(Routes!$W$6:$W$9,$C10)),0))*J10 -> 252304.21 | AA10: =INDEX(Routes!$R$6:$R$9,$C10)+IF(P10=1,INDEX(Routes!$R$6:$R$9,$C10),INDEX(Routes!$S$6:$S$9,$C10)) -> 0 | AB10: =((R10*CO2_VLSFO+S10*CO2_MGO)*INDEX(Routes!$I$6:$I$9,$C10)+(U10*INDEX(Routes!$P$6:$P$9,$C10)+V10*INDEX(Routes!$Q$6:$Q$9,$C10))*ConsPort*CO2_MGO)*PhaseIn*K10*FX -> 123936.41 | AC10: =Capacity*G10 -> 30600 | AD10: =Capacity*H10 -> 18000 | AE10: =INDEX(Routes!$J$6:$J$9,$C10)*E10 -> 65 | AF10: =INDEX(Routes!$K$6:$K$9,$C10)*E10 -> 47.5 | AG10: =AC10*AE10+AD10*AF10 -> 2844000 | AH10: =AG10*Commission -> 71100 | AI10: =Y10+Z10+AA10+AB10+MiscVoy -> 1053581 | AJ10: =N10+U10+V10+W10 -> 49.407407 | AK10: =(AG10-AH10-AI10)/AJ10 -> 34798.811 | AL10: =AG10-AH10-AI10-Benchmark*AJ10 -> 829985.7 | AM10: =IF(AC10>0,((Benchmark*AJ10+AI10)/(1-Commission)-AD10*AF10)/AC10,0) -> 37.180804 | AN10: =LOA_ft*Port_Tariffs!$C$9*IF((INDEX(Routes!$L$6:$L$9,$C10)*INDEX(Routes!$X$6:$X$9,$C10)*F10)<=2,(INDEX(Routes!$L$6:$L$9,$C10)*INDEX(Routes!$X$6:$X$9,$C10)*F10),IF((INDEX(Routes!$L$6:$L$9,$C10)*INDEX(Routes!$X$6:$X$9,$C10)*F10)<=3,2+0.9*((INDEX(Routes!$L$6:$L$9,$C10)*INDEX(Routes!$X$6:$X$9,$C10)*F10)-2),IF((INDEX(Routes!$L$6:$L$9,$C10)*INDEX(Routes!$X$6:$X$9,$C10)*F10)<=4,2.9+0.75*((INDEX(Routes!$L$6:$L$9,$C10)*INDEX(Routes!$X$6:$X$9,$C10)*F10)-3),IF((INDEX(Routes!$L$6:$L$9,$C10)*INDEX(Routes!$X$6:$X$9,$C10)*F10)<=5,3.65+0.6*((INDEX(Routes!$L$6:$L$9,$C10)*INDEX(Routes!$X$6:$X$9,$C10)*F10)-4),4.25+0.5*((INDEX(Routes!$L$6:$L$9,$C10)*INDEX(Routes!$X$6:$X$9,$C10)*F10)-5))))) -> 19557.6 | AO10: =LOA_ft*Port_Tariffs!$C$9*IF((INDEX(Routes!$M$6:$M$9,$C10)*INDEX(Routes!$Y$6:$Y$9,$C10)*F10)<=2,(INDEX(Routes!$M$6:$M$9,$C10)*INDEX(Routes!$Y$6:$Y$9,$C10)*F10),IF((INDEX(Routes!$M$6:$M$9,$C10)*INDEX(Routes!$Y$6:$Y$9,$C10)*F10)<=3,2+0.9*((INDEX(Routes!$M$6:$M$9,$C10)*INDEX(Routes!$Y$6:$Y$9,$C10)*F10)-2),IF((INDEX(Routes!$M$6:$M$9,$C10)*INDEX(Routes!$Y$6:$Y$9,$C10)*F10)<=4,2.9+0.75*((INDEX(Routes!$M$6:$M$9,$C10)*INDEX(Routes!$Y$6:$Y$9,$C10)*F10)-3),IF((INDEX(Routes!$M$6:$M$9,$C10)*INDEX(Routes!$Y$6:$Y$9,$C10)*F10)<=5,3.65+0.6*((INDEX(Routes!$M$6:$M$9,$C10)*INDEX(Routes!$Y$6:$Y$9,$C10)*F10)-4),4.25+0.5*((INDEX(Routes!$M$6:$M$9,$C10)*INDEX(Routes!$Y$6:$Y$9,$C10)*F10)-5))))) -> 0
A11: Bunker price (Brent) — low | B11: tornado | C11: =Sw_Route -> 1 | D11: =Brent_P10 -> 67.98 | E11: =FreightMult -> 1 | F11: =PortMult -> 1 | G11: =UtilFH -> 0.85 | H11: =UtilBH -> 0.5 | I11: =Speed -> 13.5 | J11: =PortCostMult -> 1 | K11: =EUA -> 75 | L11: =INDEX(Routes!$E$6:$E$9,$C11) -> 5000 | M11: =INDEX(Routes!$F$6:$F$9,$C11)/L11 -> 0.13 | N11: =2*L11*(1+SeaMargin)/(I11*24) -> 32.407407 | O11: =(I11/RefSpeed)^SpeedExp -> 1 | P11: =IF(H11>0,1,0) -> 1 | Q11: =N11/2*O11*(ConsLaden+IF(P11=1,ConsLaden,ConsBallast)) -> 875 | R11: =Q11*(1-M11) -> 761.25 | S11: =Q11*M11 -> 113.75 | T11: =1+P11 -> 2 | U11: =INDEX(Routes!$L$6:$L$9,$C11)*T11*F11 -> 10 | V11: =INDEX(Routes!$M$6:$M$9,$C11)*T11*F11 -> 7 | W11: =INDEX(Routes!$H$6:$H$9,$C11)*2 -> 0 | X11: =(U11+V11+W11)*ConsPort -> 102 | Y11: =R11*D11*VLSFO_Mult+(S11+X11)*D11*MGO_Mult -> 540740.11 | Z11: =(INDEX(Routes!$N$6:$N$9,$C11)+AN11+MIN(AC11*INDEX(Routes!$T$6:$T$9,$C11),INDEX(Routes!$V$6:$V$9,$C11))+INDEX(Routes!$O$6:$O$9,$C11)+AO11+MIN(AC11*INDEX(Routes!$U$6:$U$9,$C11),INDEX(Routes!$W$6:$W$9,$C11))+IF(P11=1,INDEX(Routes!$N$6:$N$9,$C11)+AN11+MIN(AD11*INDEX(Routes!$T$6:$T$9,$C11),INDEX(Routes!$V$6:$V$9,$C11))+INDEX(Routes!$O$6:$O$9,$C11)+AO11+MIN(AD11*INDEX(Routes!$U$6:$U$9,$C11),INDEX(Routes!$W$6:$W$9,$C11)),0))*J11 -> 252304.21 | AA11: =INDEX(Routes!$R$6:$R$9,$C11)+IF(P11=1,INDEX(Routes!$R$6:$R$9,$C11),INDEX(Routes!$S$6:$S$9,$C11)) -> 0 | AB11: =((R11*CO2_VLSFO+S11*CO2_MGO)*INDEX(Routes!$I$6:$I$9,$C11)+(U11*INDEX(Routes!$P$6:$P$9,$C11)+V11*INDEX(Routes!$Q$6:$Q$9,$C11))*ConsPort*CO2_MGO)*PhaseIn*K11*FX -> 123936.41 | AC11: =Capacity*G11 -> 30600 | AD11: =Capacity*H11 -> 18000 | AE11: =INDEX(Routes!$J$6:$J$9,$C11)*E11 -> 52 | AF11: =INDEX(Routes!$K$6:$K$9,$C11)*E11 -> 38 | AG11: =AC11*AE11+AD11*AF11 -> 2275200 | AH11: =AG11*Commission -> 56880 | AI11: =Y11+Z11+AA11+AB11+MiscVoy -> 941980.73 | AJ11: =N11+U11+V11+W11 -> 49.407407 | AK11: =(AG11-AH11-AI11)/AJ11 -> 25832.954 | AL11: =AG11-AH11-AI11-Benchmark*AJ11 -> 387005.94 | AM11: =IF(AC11>0,((Benchmark*AJ11+AI11)/(1-Commission)-AD11*AF11)/AC11,0) -> 39.028459 | AN11: =LOA_ft*Port_Tariffs!$C$9*IF((INDEX(Routes!$L$6:$L$9,$C11)*INDEX(Routes!$X$6:$X$9,$C11)*F11)<=2,(INDEX(Routes!$L$6:$L$9,$C11)*INDEX(Routes!$X$6:$X$9,$C11)*F11),IF((INDEX(Routes!$L$6:$L$9,$C11)*INDEX(Routes!$X$6:$X$9,$C11)*F11)<=3,2+0.9*((INDEX(Routes!$L$6:$L$9,$C11)*INDEX(Routes!$X$6:$X$9,$C11)*F11)-2),IF((INDEX(Routes!$L$6:$L$9,$C11)*INDEX(Routes!$X$6:$X$9,$C11)*F11)<=4,2.9+0.75*((INDEX(Routes!$L$6:$L$9,$C11)*INDEX(Routes!$X$6:$X$9,$C11)*F11)-3),IF((INDEX(Routes!$L$6:$L$9,$C11)*INDEX(Routes!$X$6:$X$9,$C11)*F11)<=5,3.65+0.6*((INDEX(Routes!$L$6:$L$9,$C11)*INDEX(Routes!$X$6:$X$9,$C11)*F11)-4),4.25+0.5*((INDEX(Routes!$L$6:$L$9,$C11)*INDEX(Routes!$X$6:$X$9,$C11)*F11)-5))))) -> 19557.6 | AO11: =LOA_ft*Port_Tariffs!$C$9*IF((INDEX(Routes!$M$6:$M$9,$C11)*INDEX(Routes!$Y$6:$Y$9,$C11)*F11)<=2,(INDEX(Routes!$M$6:$M$9,$C11)*INDEX(Routes!$Y$6:$Y$9,$C11)*F11),IF((INDEX(Routes!$M$6:$M$9,$C11)*INDEX(Routes!$Y$6:$Y$9,$C11)*F11)<=3,2+0.9*((INDEX(Routes!$M$6:$M$9,$C11)*INDEX(Routes!$Y$6:$Y$9,$C11)*F11)-2),IF((INDEX(Routes!$M$6:$M$9,$C11)*INDEX(Routes!$Y$6:$Y$9,$C11)*F11)<=4,2.9+0.75*((INDEX(Routes!$M$6:$M$9,$C11)*INDEX(Routes!$Y$6:$Y$9,$C11)*F11)-3),IF((INDEX(Routes!$M$6:$M$9,$C11)*INDEX(Routes!$Y$6:$Y$9,$C11)*F11)<=5,3.65+0.6*((INDEX(Routes!$M$6:$M$9,$C11)*INDEX(Routes!$Y$6:$Y$9,$C11)*F11)-4),4.25+0.5*((INDEX(Routes!$M$6:$M$9,$C11)*INDEX(Routes!$Y$6:$Y$9,$C11)*F11)-5))))) -> 0
